Workbook

Sheet How To
A1: Star City Cup tracker
A2: Fill in the white columns. Grey columns calculate themselves. Every tab has a Check column that says OK or tells you what to fix.
A3: All scores are strokes. Lower scores rank higher. Players are picked from the Players tab, so add new players there first.
A5: Each week
A6: 1. On the OHW tab, find this week's block, pick the players, enter their gross scores, and pick the gross and net winners.
A7: 2. Update any Major or Club Championship in progress with players' new best scores.
A8: 3. Enter any league seasons that finished.
A9: Last Week fills itself: the first time a new week's OHW score is entered, the Star City Cup script saves the standings from before that week. (The script is installed once; see the setup guide.)
A11: Tabs
A12: Club Championship: one row per qualifier with their best qualifying score. Pick the bracket result for the top 16 as they're knocked out. Until then, top 16 players are projected at Round of 16 points.
A13: Masters, US Open, The Open, PGA Championship: one row per player with their best score so far. When the Major ends, pick one Winner in each division (Open and Senior). The winner gets 600; anyone tied with the winner is scored from 2nd place down.
A14: Status (Club Championship and Majors): Not started means no points yet. In progress means points are projected from the current leaderboard. Final means points are official, and the script locks the score column (you'll be warned before changing a locked score).
... A19: Web Feed: collects every tab for the web page. Don't edit it, rename it, or change its headings.

Sheet Standings
A1: Rank | B1: Player | C1: Cup Total | D1: Club Championship | E1: Majors | F1: Scramble League | G1: Tuesday Night League | H1: OHW (best 12) | I1: OHW weeks played | J1: Last Week Rank | K1: Move
A2: =IF($B2="","",RANK($C2,$C$2:$C$500)) | B2: =IF(Players!$A2="","",Players!$A2) | C2: =IF($B2="","",SUM(D2:H2)) | D2: =IF($B2="","",SUMIFS('Web Feed'!$O$2:$O$3015,'Web Feed'!$B$2:$B$3015,Points!$A$2,'Web Feed'!$F$2:$F$3015,$B2)+SUMIFS('Web Feed'!$O$2:$O$3015,'Web Feed'!$B$2:$B$3015,Points!$A$2,'Web Feed'!$G$2:$G$3015,$B2)+SUMIFS('Web Feed'!$O$2:$O$3015,'Web Feed'!$B$2:$B$3015,Points!$A$2,'Web Feed'!$H$2:$H$3015,$B2)+SUMIFS('Web Feed'!$O$2:$O$3015,'Web Feed'!$B$2:$B$3015,Points!$A$2,'Web Feed'!$I$2:$I$3015,$B2)) | E2: =IF($B2="","",SUMIFS('Web Feed'!$O$2:$O$3015,'Web Feed'!$B$2:$B$3015,Points!$A$3,'Web Feed'!$F$2:$F$3015,$B2)+SUMIFS('Web Feed'!$O$2:$O$3015,'Web Feed'!$B$2:$B$3015,Points!$A$3,'Web Feed'!$G$2:$G$3015,$B2)+SUMIFS('Web Feed'!$O$2:$O$3015,'Web Feed'!$B$2:$B$3015,Points!$A$3,'Web Feed'!$H$2:$H$3015,$B2)+SUMIFS('Web Feed'!$O$2:$O$3015,'Web Feed'!$B$2:$B$3015,Points!$A$3,'Web Feed'!$I$2:$I$3015,$B2)) | F2: =IF($B2="","",SUMIFS('Web Feed'!$O$2:$O$3015,'Web Feed'!$B$2:$B$3015,Points!$A$4,'Web Feed'!$F$2:$F$3015,$B2)+SUMIFS('Web Feed'!$O$2:$O$3015,'Web Feed'!$B$2:$B$3015,Points!$A$4,'Web Feed'!$G$2:$G$3015,$B2)+SUMIFS('Web Feed'!$O$2:$O$3015,'Web Feed'!$B$2:$B$3015,Points!$A$4,'Web Feed'!$H$2:$H$3015,$B2)+SUMIFS('Web Feed'!$O$2:$O$3015,'Web Feed'!$B$2:$B$3015,Points!$A$4,'Web Feed'!$I$2:$I$3015,$B2)) | G2: =IF($B2="","",SUMIFS('Web Feed'!$O$2:$O$3015,'Web Feed'!$B$2:$B$3015,Points!$A$5,'Web Feed'!$F$2:$F$3015,$B2)+SUMIFS('Web Feed'!$O$2:$O$3015,'Web Feed'!$B$2:$B$3015,Points!$A$5,'Web Feed'!$G$2:$G$3015,$B2)+SUMIFS('Web Feed'!$O$2:$O$3015,'Web Feed'!$B$2:$B$3015,Points!$A$5,'Web Feed'!$H$2:$H$3015,$B2)+SUMIFS('Web Feed'!$O$2:$O$3015,'Web Feed'!$B$2:$B$3015,Points!$A$5,'Web Feed'!$I$2:$I$3015,$B2)) | H2: =IF($B2="","",SUMIFS('Web Feed'!$O$2:$O$3015,'Web Feed'!$B$2:$B$3015,Points!$A$6,'Web Feed'!$F$2:$F$3015,$B2)+SUMIFS('Web Feed'!$O$2:$O$3015,'Web Feed'!$B$2:$B$3015,Points!$A$6,'Web Feed'!$G$2:$G$3015,$B2)+SUMIFS('Web Feed'!$O$2:$O$3015,'Web Feed'!$B$2:$B$3015,Points!$A$6,'Web Feed'!$H$2:$H$3015,$B2)+SUMIFS('Web Feed'!$O$2:$O$3015,'Web Feed'!$B$2:$B$3015,Points!$A$6,'Web Feed'!$I$2:$I$3015,$B2)) | I2: =IF($B2="","",COUNTIFS('Web Feed'!$B$2:$B$3015,"OHW",'Web Feed'!$F$2:$F$3015,$B2)) | J2: =IF($B2="","",IFERROR(INDEX('Last Week'!$A$2:$A$301,MATCH($B2,'Last Week'!$B$2:$B$301,0)),"")) | K2: =IF(OR($B2="",$J2=""),"",$J2-$A2)
A3: =IF($B3="","",RANK($C3,$C$2:$C$500)) | B3: =IF(Players!$A3="","",Players!$A3) | C3: =IF($B3="","",SUM(D3:H3)) | D3: =IF($B3="","",SUMIFS('Web Feed'!$O$2:$O$3015,'Web Feed'!$B$2:$B$3015,Points!$A$2,'Web Feed'!$F$2:$F$3015,$B3)+SUMIFS('Web Feed'!$O$2:$O$3015,'Web Feed'!$B$2:$B$3015,Points!$A$2,'Web Feed'!$G$2:$G$3015,$B3)+SUMIFS('Web Feed'!$O$2:$O$3015,'Web Feed'!$B$2:$B$3015,Points!$A$2,'Web Feed'!$H$2:$H$3015,$B3)+SUMIFS('Web Feed'!$O$2:$O$3015,'Web Feed'!$B$2:$B$3015,Points!$A$2,'Web Feed'!$I$2:$I$3015,$B3)) | E3: =IF($B3="","",SUMIFS('Web Feed'!$O$2:$O$3015,'Web Feed'!$B$2:$B$3015,Points!$A$3,'Web Feed'!$F$2:$F$3015,$B3)+SUMIFS('Web Feed'!$O$2:$O$3015,'Web Feed'!$B$2:$B$3015,Points!$A$3,'Web Feed'!$G$2:$G$3015,$B3)+SUMIFS('Web Feed'!$O$2:$O$3015,'Web Feed'!$B$2:$B$3015,Points!$A$3,'Web Feed'!$H$2:$H$3015,$B3)+SUMIFS('Web Feed'!$O$2:$O$3015,'Web Feed'!$B$2:$B$3015,Points!$A$3,'Web Feed'!$I$2:$I$3015,$B3)) | F3: =IF($B3="","",SUMIFS('Web Feed'!$O$2:$O$3015,'Web Feed'!$B$2:$B$3015,Points!$A$4,'Web Feed'!$F$2:$F$3015,$B3)+SUMIFS('Web Feed'!$O$2:$O$3015,'Web Feed'!$B$2:$B$3015,Points!$A$4,'Web Feed'!$G$2:$G$3015,$B3)+SUMIFS('Web Feed'!$O$2:$O$3015,'Web Feed'!$B$2:$B$3015,Points!$A$4,'Web Feed'!$H$2:$H$3015,$B3)+SUMIFS('Web Feed'!$O$2:$O$3015,'Web Feed'!$B$2:$B$3015,Points!$A$4,'Web Feed'!$I$2:$I$3015,$B3)) | G3: =IF($B3="","",SUMIFS('Web Feed'!$O$2:$O$3015,'Web Feed'!$B$2:$B$3015,Points!$A$5,'Web Feed'!$F$2:$F$3015,$B3)+SUMIFS('Web Feed'!$O$2:$O$3015,'Web Feed'!$B$2:$B$3015,Points!$A$5,'Web Feed'!$G$2:$G$3015,$B3)+SUMIFS('Web Feed'!$O$2:$O$3015,'Web Feed'!$B$2:$B$3015,Points!$A$5,'Web Feed'!$H$2:$H$3015,$B3)+SUMIFS('Web Feed'!$O$2:$O$3015,'Web Feed'!$B$2:$B$3015,Points!$A$5,'Web Feed'!$I$2:$I$3015,$B3)) | H3: =IF($B3="","",SUMIFS('Web Feed'!$O$2:$O$3015,'Web Feed'!$B$2:$B$3015,Points!$A$6,'Web Feed'!$F$2:$F$3015,$B3)+SUMIFS('Web Feed'!$O$2:$O$3015,'Web Feed'!$B$2:$B$3015,Points!$A$6,'Web Feed'!$G$2:$G$3015,$B3)+SUMIFS('Web Feed'!$O$2:$O$3015,'Web Feed'!$B$2:$B$3015,Points!$A$6,'Web Feed'!$H$2:$H$3015,$B3)+SUMIFS('Web Feed'!$O$2:$O$3015,'Web Feed'!$B$2:$B$3015,Points!$A$6,'Web Feed'!$I$2:$I$3015,$B3)) | I3: =IF($B3="","",COUNTIFS('Web Feed'!$B$2:$B$3015,"OHW",'Web Feed'!$F$2:$F$3015,$B3)) | J3: =IF($B3="","",IFERROR(INDEX('Last Week'!$A$2:$A$301,MATCH($B3,'Last Week'!$B$2:$B$301,0)),"")) | K3: =IF(OR($B3="",$J3=""),"",$J3-$A3)
A4: =IF($B4="","",RANK($C4,$C$2:$C$500)) | B4: =IF(Players!$A4="","",Players!$A4) | C4: =IF($B4="","",SUM(D4:H4)) | D4: =IF($B4="","",SUMIFS('Web Feed'!$O$2:$O$3015,'Web Feed'!$B$2:$B$3015,Points!$A$2,'Web Feed'!$F$2:$F$3015,$B4)+SUMIFS('Web Feed'!$O$2:$O$3015,'Web Feed'!$B$2:$B$3015,Points!$A$2,'Web Feed'!$G$2:$G$3015,$B4)+SUMIFS('Web Feed'!$O$2:$O$3015,'Web Feed'!$B$2:$B$3015,Points!$A$2,'Web Feed'!$H$2:$H$3015,$B4)+SUMIFS('Web Feed'!$O$2:$O$3015,'Web Feed'!$B$2:$B$3015,Points!$A$2,'Web Feed'!$I$2:$I$3015,$B4)) | E4: =IF($B4="","",SUMIFS('Web Feed'!$O$2:$O$3015,'Web Feed'!$B$2:$B$3015,Points!$A$3,'Web Feed'!$F$2:$F$3015,$B4)+SUMIFS('Web Feed'!$O$2:$O$3015,'Web Feed'!$B$2:$B$3015,Points!$A$3,'Web Feed'!$G$2:$G$3015,$B4)+SUMIFS('Web Feed'!$O$2:$O$3015,'Web Feed'!$B$2:$B$3015,Points!$A$3,'Web Feed'!$H$2:$H$3015,$B4)+SUMIFS('Web Feed'!$O$2:$O$3015,'Web Feed'!$B$2:$B$3015,Points!$A$3,'Web Feed'!$I$2:$I$3015,$B4)) | F4: =IF($B4="","",SUMIFS('Web Feed'!$O$2:$O$3015,'Web Feed'!$B$2:$B$3015,Points!$A$4,'Web Feed'!$F$2:$F$3015,$B4)+SUMIFS('Web Feed'!$O$2:$O$3015,'Web Feed'!$B$2:$B$3015,Points!$A$4,'Web Feed'!$G$2:$G$3015,$B4)+SUMIFS('Web Feed'!$O$2:$O$3015,'Web Feed'!$B$2:$B$3015,Points!$A$4,'Web Feed'!$H$2:$H$3015,$B4)+SUMIFS('Web Feed'!$O$2:$O$3015,'Web Feed'!$B$2:$B$3015,Points!$A$4,'Web Feed'!$I$2:$I$3015,$B4)) | G4: =IF($B4="","",SUMIFS('Web Feed'!$O$2:$O$3015,'Web Feed'!$B$2:$B$3015,Points!$A$5,'Web Feed'!$F$2:$F$3015,$B4)+SUMIFS('Web Feed'!$O$2:$O$3015,'Web Feed'!$B$2:$B$3015,Points!$A$5,'Web Feed'!$G$2:$G$3015,$B4)+SUMIFS('Web Feed'!$O$2:$O$3015,'Web Feed'!$B$2:$B$3015,Points!$A$5,'Web Feed'!$H$2:$H$3015,$B4)+SUMIFS('Web Feed'!$O$2:$O$3015,'Web Feed'!$B$2:$B$3015,Points!$A$5,'Web Feed'!$I$2:$I$3015,$B4)) | H4: =IF($B4="","",SUMIFS('Web Feed'!$O$2:$O$3015,'Web Feed'!$B$2:$B$3015,Points!$A$6,'Web Feed'!$F$2:$F$3015,$B4)+SUMIFS('Web Feed'!$O$2:$O$3015,'Web Feed'!$B$2:$B$3015,Points!$A$6,'Web Feed'!$G$2:$G$3015,$B4)+SUMIFS('Web Feed'!$O$2:$O$3015,'Web Feed'!$B$2:$B$3015,Points!$A$6,'Web Feed'!$H$2:$H$3015,$B4)+SUMIFS('Web Feed'!$O$2:$O$3015,'Web Feed'!$B$2:$B$3015,Points!$A$6,'Web Feed'!$I$2:$I$3015,$B4)) | I4: =IF($B4="","",COUNTIFS('Web Feed'!$B$2:$B$3015,"OHW",'Web Feed'!$F$2:$F$3015,$B4)) | J4: =IF($B4="","",IFERROR(INDEX('Last Week'!$A$2:$A$301,MATCH($B4,'Last Week'!$B$2:$B$301,0)),"")) | K4: =IF(OR($B4="",$J4=""),"",$J4-$A4)
A5: =IF($B5="","",RANK($C5,$C$2:$C$500)) | B5: =IF(Players!$A5="","",Players!$A5) | C5: =IF($B5="","",SUM(D5:H5)) | D5: =IF($B5="","",SUMIFS('Web Feed'!$O$2:$O$3015,'Web Feed'!$B$2:$B$3015,Points!$A$2,'Web Feed'!$F$2:$F$3015,$B5)+SUMIFS('Web Feed'!$O$2:$O$3015,'Web Feed'!$B$2:$B$3015,Points!$A$2,'Web Feed'!$G$2:$G$3015,$B5)+SUMIFS('Web Feed'!$O$2:$O$3015,'Web Feed'!$B$2:$B$3015,Points!$A$2,'Web Feed'!$H$2:$H$3015,$B5)+SUMIFS('Web Feed'!$O$2:$O$3015,'Web Feed'!$B$2:$B$3015,Points!$A$2,'Web Feed'!$I$2:$I$3015,$B5)) | E5: =IF($B5="","",SUMIFS('Web Feed'!$O$2:$O$3015,'Web Feed'!$B$2:$B$3015,Points!$A$3,'Web Feed'!$F$2:$F$3015,$B5)+SUMIFS('Web Feed'!$O$2:$O$3015,'Web Feed'!$B$2:$B$3015,Points!$A$3,'Web Feed'!$G$2:$G$3015,$B5)+SUMIFS('Web Feed'!$O$2:$O$3015,'Web Feed'!$B$2:$B$3015,Points!$A$3,'Web Feed'!$H$2:$H$3015,$B5)+SUMIFS('Web Feed'!$O$2:$O$3015,'Web Feed'!$B$2:$B$3015,Points!$A$3,'Web Feed'!$I$2:$I$3015,$B5)) | F5: =IF($B5="","",SUMIFS('Web Feed'!$O$2:$O$3015,'Web Feed'!$B$2:$B$3015,Points!$A$4,'Web Feed'!$F$2:$F$3015,$B5)+SUMIFS('Web Feed'!$O$2:$O$3015,'Web Feed'!$B$2:$B$3015,Points!$A$4,'Web Feed'!$G$2:$G$3015,$B5)+SUMIFS('Web Feed'!$O$2:$O$3015,'Web Feed'!$B$2:$B$3015,Points!$A$4,'Web Feed'!$H$2:$H$3015,$B5)+SUMIFS('Web Feed'!$O$2:$O$3015,'Web Feed'!$B$2:$B$3015,Points!$A$4,'Web Feed'!$I$2:$I$3015,$B5)) | G5: =IF($B5="","",SUMIFS('Web Feed'!$O$2:$O$3015,'Web Feed'!$B$2:$B$3015,Points!$A$5,'Web Feed'!$F$2:$F$3015,$B5)+SUMIFS('Web Feed'!$O$2:$O$3015,'Web Feed'!$B$2:$B$3015,Points!$A$5,'Web Feed'!$G$2:$G$3015,$B5)+SUMIFS('Web Feed'!$O$2:$O$3015,'Web Feed'!$B$2:$B$3015,Points!$A$5,'Web Feed'!$H$2:$H$3015,$B5)+SUMIFS('Web Feed'!$O$2:$O$3015,'Web Feed'!$B$2:$B$3015,Points!$A$5,'Web Feed'!$I$2:$I$3015,$B5)) | H5: =IF($B5="","",SUMIFS('Web Feed'!$O$2:$O$3015,'Web Feed'!$B$2:$B$3015,Points!$A$6,'Web Feed'!$F$2:$F$3015,$B5)+SUMIFS('Web Feed'!$O$2:$O$3015,'Web Feed'!$B$2:$B$3015,Points!$A$6,'Web Feed'!$G$2:$G$3015,$B5)+SUMIFS('Web Feed'!$O$2:$O$3015,'Web Feed'!$B$2:$B$3015,Points!$A$6,'Web Feed'!$H$2:$H$3015,$B5)+SUMIFS('Web Feed'!$O$2:$O$3015,'Web Feed'!$B$2:$B$3015,Points!$A$6,'Web Feed'!$I$2:$I$3015,$B5)) | I5: =IF($B5="","",COUNTIFS('Web Feed'!$B$2:$B$3015,"OHW",'Web Feed'!$F$2:$F$3015,$B5)) | J5: =IF($B5="","",IFERROR(INDEX('Last Week'!$A$2:$A$301,MATCH($B5,'Last Week'!$B$2:$B$301,0)),"")) | K5: =IF(OR($B5="",$J5=""),"",$J5-$A5)
A6: =IF($B6="","",RANK($C6,$C$2:$C$500)) | B6: =IF(Players!$A6="","",Players!$A6) | C6: =IF($B6="","",SUM(D6:H6)) | D6: =IF($B6="","",SUMIFS('Web Feed'!$O$2:$O$3015,'Web Feed'!$B$2:$B$3015,Points!$A$2,'Web Feed'!$F$2:$F$3015,$B6)+SUMIFS('Web Feed'!$O$2:$O$3015,'Web Feed'!$B$2:$B$3015,Points!$A$2,'Web Feed'!$G$2:$G$3015,$B6)+SUMIFS('Web Feed'!$O$2:$O$3015,'Web Feed'!$B$2:$B$3015,Points!$A$2,'Web Feed'!$H$2:$H$3015,$B6)+SUMIFS('Web Feed'!$O$2:$O$3015,'Web Feed'!$B$2:$B$3015,Points!$A$2,'Web Feed'!$I$2:$I$3015,$B6)) | E6: =IF($B6="","",SUMIFS('Web Feed'!$O$2:$O$3015,'Web Feed'!$B$2:$B$3015,Points!$A$3,'Web Feed'!$F$2:$F$3015,$B6)+SUMIFS('Web Feed'!$O$2:$O$3015,'Web Feed'!$B$2:$B$3015,Points!$A$3,'Web Feed'!$G$2:$G$3015,$B6)+SUMIFS('Web Feed'!$O$2:$O$3015,'Web Feed'!$B$2:$B$3015,Points!$A$3,'Web Feed'!$H$2:$H$3015,$B6)+SUMIFS('Web Feed'!$O$2:$O$3015,'Web Feed'!$B$2:$B$3015,Points!$A$3,'Web Feed'!$I$2:$I$3015,$B6)) | F6: =IF($B6="","",SUMIFS('Web Feed'!$O$2:$O$3015,'Web Feed'!$B$2:$B$3015,Points!$A$4,'Web Feed'!$F$2:$F$3015,$B6)+SUMIFS('Web Feed'!$O$2:$O$3015,'Web Feed'!$B$2:$B$3015,Points!$A$4,'Web Feed'!$G$2:$G$3015,$B6)+SUMIFS('Web Feed'!$O$2:$O$3015,'Web Feed'!$B$2:$B$3015,Points!$A$4,'Web Feed'!$H$2:$H$3015,$B6)+SUMIFS('Web Feed'!$O$2:$O$3015,'Web Feed'!$B$2:$B$3015,Points!$A$4,'Web Feed'!$I$2:$I$3015,$B6)) | G6: =IF($B6="","",SUMIFS('Web Feed'!$O$2:$O$3015,'Web Feed'!$B$2:$B$3015,Points!$A$5,'Web Feed'!$F$2:$F$3015,$B6)+SUMIFS('Web Feed'!$O$2:$O$3015,'Web Feed'!$B$2:$B$3015,Points!$A$5,'Web Feed'!$G$2:$G$3015,$B6)+SUMIFS('Web Feed'!$O$2:$O$3015,'Web Feed'!$B$2:$B$3015,Points!$A$5,'Web Feed'!$H$2:$H$3015,$B6)+SUMIFS('Web Feed'!$O$2:$O$3015,'Web Feed'!$B$2:$B$3015,Points!$A$5,'Web Feed'!$I$2:$I$3015,$B6)) | H6: =IF($B6="","",SUMIFS('Web Feed'!$O$2:$O$3015,'Web Feed'!$B$2:$B$3015,Points!$A$6,'Web Feed'!$F$2:$F$3015,$B6)+SUMIFS('Web Feed'!$O$2:$O$3015,'Web Feed'!$B$2:$B$3015,Points!$A$6,'Web Feed'!$G$2:$G$3015,$B6)+SUMIFS('Web Feed'!$O$2:$O$3015,'Web Feed'!$B$2:$B$3015,Points!$A$6,'Web Feed'!$H$2:$H$3015,$B6)+SUMIFS('Web Feed'!$O$2:$O$3015,'Web Feed'!$B$2:$B$3015,Points!$A$6,'Web Feed'!$I$2:$I$3015,$B6)) | I6: =IF($B6="","",COUNTIFS('Web Feed'!$B$2:$B$3015,"OHW",'Web Feed'!$F$2:$F$3015,$B6)) | J6: =IF($B6="","",IFERROR(INDEX('Last Week'!$A$2:$A$301,MATCH($B6,'Last Week'!$B$2:$B$301,0)),"")) | K6: =IF(OR($B6="",$J6=""),"",$J6-$A6)
A7: =IF($B7="","",RANK($C7,$C$2:$C$500)) | B7: =IF(Players!$A7="","",Players!$A7) | C7: =IF($B7="","",SUM(D7:H7)) | D7: =IF($B7="","",SUMIFS('Web Feed'!$O$2:$O$3015,'Web Feed'!$B$2:$B$3015,Points!$A$2,'Web Feed'!$F$2:$F$3015,$B7)+SUMIFS('Web Feed'!$O$2:$O$3015,'Web Feed'!$B$2:$B$3015,Points!$A$2,'Web Feed'!$G$2:$G$3015,$B7)+SUMIFS('Web Feed'!$O$2:$O$3015,'Web Feed'!$B$2:$B$3015,Points!$A$2,'Web Feed'!$H$2:$H$3015,$B7)+SUMIFS('Web Feed'!$O$2:$O$3015,'Web Feed'!$B$2:$B$3015,Points!$A$2,'Web Feed'!$I$2:$I$3015,$B7)) | E7: =IF($B7="","",SUMIFS('Web Feed'!$O$2:$O$3015,'Web Feed'!$B$2:$B$3015,Points!$A$3,'Web Feed'!$F$2:$F$3015,$B7)+SUMIFS('Web Feed'!$O$2:$O$3015,'Web Feed'!$B$2:$B$3015,Points!$A$3,'Web Feed'!$G$2:$G$3015,$B7)+SUMIFS('Web Feed'!$O$2:$O$3015,'Web Feed'!$B$2:$B$3015,Points!$A$3,'Web Feed'!$H$2:$H$3015,$B7)+SUMIFS('Web Feed'!$O$2:$O$3015,'Web Feed'!$B$2:$B$3015,Points!$A$3,'Web Feed'!$I$2:$I$3015,$B7)) | F7: =IF($B7="","",SUMIFS('Web Feed'!$O$2:$O$3015,'Web Feed'!$B$2:$B$3015,Points!$A$4,'Web Feed'!$F$2:$F$3015,$B7)+SUMIFS('Web Feed'!$O$2:$O$3015,'Web Feed'!$B$2:$B$3015,Points!$A$4,'Web Feed'!$G$2:$G$3015,$B7)+SUMIFS('Web Feed'!$O$2:$O$3015,'Web Feed'!$B$2:$B$3015,Points!$A$4,'Web Feed'!$H$2:$H$3015,$B7)+SUMIFS('Web Feed'!$O$2:$O$3015,'Web Feed'!$B$2:$B$3015,Points!$A$4,'Web Feed'!$I$2:$I$3015,$B7)) | G7: =IF($B7="","",SUMIFS('Web Feed'!$O$2:$O$3015,'Web Feed'!$B$2:$B$3015,Points!$A$5,'Web Feed'!$F$2:$F$3015,$B7)+SUMIFS('Web Feed'!$O$2:$O$3015,'Web Feed'!$B$2:$B$3015,Points!$A$5,'Web Feed'!$G$2:$G$3015,$B7)+SUMIFS('Web Feed'!$O$2:$O$3015,'Web Feed'!$B$2:$B$3015,Points!$A$5,'Web Feed'!$H$2:$H$3015,$B7)+SUMIFS('Web Feed'!$O$2:$O$3015,'Web Feed'!$B$2:$B$3015,Points!$A$5,'Web Feed'!$I$2:$I$3015,$B7)) | H7: =IF($B7="","",SUMIFS('Web Feed'!$O$2:$O$3015,'Web Feed'!$B$2:$B$3015,Points!$A$6,'Web Feed'!$F$2:$F$3015,$B7)+SUMIFS('Web Feed'!$O$2:$O$3015,'Web Feed'!$B$2:$B$3015,Points!$A$6,'Web Feed'!$G$2:$G$3015,$B7)+SUMIFS('Web Feed'!$O$2:$O$3015,'Web Feed'!$B$2:$B$3015,Points!$A$6,'Web Feed'!$H$2:$H$3015,$B7)+SUMIFS('Web Feed'!$O$2:$O$3015,'Web Feed'!$B$2:$B$3015,Points!$A$6,'Web Feed'!$I$2:$I$3015,$B7)) | I7: =IF($B7="","",COUNTIFS('Web Feed'!$B$2:$B$3015,"OHW",'Web Feed'!$F$2:$F$3015,$B7)) | J7: =IF($B7="","",IFERROR(INDEX('Last Week'!$A$2:$A$301,MATCH($B7,'Last Week'!$B$2:$B$301,0)),"")) | K7: =IF(OR($B7="",$J7=""),"",$J7-$A7)
A8: =IF($B8="","",RANK($C8,$C$2:$C$500)) | B8: =IF(Players!$A8="","",Players!$A8) | C8: =IF($B8="","",SUM(D8:H8)) | D8: =IF($B8="","",SUMIFS('Web Feed'!$O$2:$O$3015,'Web Feed'!$B$2:$B$3015,Points!$A$2,'Web Feed'!$F$2:$F$3015,$B8)+SUMIFS('Web Feed'!$O$2:$O$3015,'Web Feed'!$B$2:$B$3015,Points!$A$2,'Web Feed'!$G$2:$G$3015,$B8)+SUMIFS('Web Feed'!$O$2:$O$3015,'Web Feed'!$B$2:$B$3015,Points!$A$2,'Web Feed'!$H$2:$H$3015,$B8)+SUMIFS('Web Feed'!$O$2:$O$3015,'Web Feed'!$B$2:$B$3015,Points!$A$2,'Web Feed'!$I$2:$I$3015,$B8)) | E8: =IF($B8="","",SUMIFS('Web Feed'!$O$2:$O$3015,'Web Feed'!$B$2:$B$3015,Points!$A$3,'Web Feed'!$F$2:$F$3015,$B8)+SUMIFS('Web Feed'!$O$2:$O$3015,'Web Feed'!$B$2:$B$3015,Points!$A$3,'Web Feed'!$G$2:$G$3015,$B8)+SUMIFS('Web Feed'!$O$2:$O$3015,'Web Feed'!$B$2:$B$3015,Points!$A$3,'Web Feed'!$H$2:$H$3015,$B8)+SUMIFS('Web Feed'!$O$2:$O$3015,'Web Feed'!$B$2:$B$3015,Points!$A$3,'Web Feed'!$I$2:$I$3015,$B8)) | F8: =IF($B8="","",SUMIFS('Web Feed'!$O$2:$O$3015,'Web Feed'!$B$2:$B$3015,Points!$A$4,'Web Feed'!$F$2:$F$3015,$B8)+SUMIFS('Web Feed'!$O$2:$O$3015,'Web Feed'!$B$2:$B$3015,Points!$A$4,'Web Feed'!$G$2:$G$3015,$B8)+SUMIFS('Web Feed'!$O$2:$O$3015,'Web Feed'!$B$2:$B$3015,Points!$A$4,'Web Feed'!$H$2:$H$3015,$B8)+SUMIFS('Web Feed'!$O$2:$O$3015,'Web Feed'!$B$2:$B$3015,Points!$A$4,'Web Feed'!$I$2:$I$3015,$B8)) | G8: =IF($B8="","",SUMIFS('Web Feed'!$O$2:$O$3015,'Web Feed'!$B$2:$B$3015,Points!$A$5,'Web Feed'!$F$2:$F$3015,$B8)+SUMIFS('Web Feed'!$O$2:$O$3015,'Web Feed'!$B$2:$B$3015,Points!$A$5,'Web Feed'!$G$2:$G$3015,$B8)+SUMIFS('Web Feed'!$O$2:$O$3015,'Web Feed'!$B$2:$B$3015,Points!$A$5,'Web Feed'!$H$2:$H$3015,$B8)+SUMIFS('Web Feed'!$O$2:$O$3015,'Web Feed'!$B$2:$B$3015,Points!$A$5,'Web Feed'!$I$2:$I$3015,$B8)) | H8: =IF($B8="","",SUMIFS('Web Feed'!$O$2:$O$3015,'Web Feed'!$B$2:$B$3015,Points!$A$6,'Web Feed'!$F$2:$F$3015,$B8)+SUMIFS('Web Feed'!$O$2:$O$3015,'Web Feed'!$B$2:$B$3015,Points!$A$6,'Web Feed'!$G$2:$G$3015,$B8)+SUMIFS('Web Feed'!$O$2:$O$3015,'Web Feed'!$B$2:$B$3015,Points!$A$6,'Web Feed'!$H$2:$H$3015,$B8)+SUMIFS('Web Feed'!$O$2:$O$3015,'Web Feed'!$B$2:$B$3015,Points!$A$6,'Web Feed'!$I$2:$I$3015,$B8)) | I8: =IF($B8="","",COUNTIFS('Web Feed'!$B$2:$B$3015,"OHW",'Web Feed'!$F$2:$F$3015,$B8)) | J8: =IF($B8="","",IFERROR(INDEX('Last Week'!$A$2:$A$301,MATCH($B8,'Last Week'!$B$2:$B$301,0)),"")) | K8: =IF(OR($B8="",$J8=""),"",$J8-$A8)
A9: =IF($B9="","",RANK($C9,$C$2:$C$500)) | B9: =IF(Players!$A9="","",Players!$A9) | C9: =IF($B9="","",SUM(D9:H9)) | D9: =IF($B9="","",SUMIFS('Web Feed'!$O$2:$O$3015,'Web Feed'!$B$2:$B$3015,Points!$A$2,'Web Feed'!$F$2:$F$3015,$B9)+SUMIFS('Web Feed'!$O$2:$O$3015,'Web Feed'!$B$2:$B$3015,Points!$A$2,'Web Feed'!$G$2:$G$3015,$B9)+SUMIFS('Web Feed'!$O$2:$O$3015,'Web Feed'!$B$2:$B$3015,Points!$A$2,'Web Feed'!$H$2:$H$3015,$B9)+SUMIFS('Web Feed'!$O$2:$O$3015,'Web Feed'!$B$2:$B$3015,Points!$A$2,'Web Feed'!$I$2:$I$3015,$B9)) | E9: =IF($B9="","",SUMIFS('Web Feed'!$O$2:$O$3015,'Web Feed'!$B$2:$B$3015,Points!$A$3,'Web Feed'!$F$2:$F$3015,$B9)+SUMIFS('Web Feed'!$O$2:$O$3015,'Web Feed'!$B$2:$B$3015,Points!$A$3,'Web Feed'!$G$2:$G$3015,$B9)+SUMIFS('Web Feed'!$O$2:$O$3015,'Web Feed'!$B$2:$B$3015,Points!$A$3,'Web Feed'!$H$2:$H$3015,$B9)+SUMIFS('Web Feed'!$O$2:$O$3015,'Web Feed'!$B$2:$B$3015,Points!$A$3,'Web Feed'!$I$2:$I$3015,$B9)) | F9: =IF($B9="","",SUMIFS('Web Feed'!$O$2:$O$3015,'Web Feed'!$B$2:$B$3015,Points!$A$4,'Web Feed'!$F$2:$F$3015,$B9)+SUMIFS('Web Feed'!$O$2:$O$3015,'Web Feed'!$B$2:$B$3015,Points!$A$4,'Web Feed'!$G$2:$G$3015,$B9)+SUMIFS('Web Feed'!$O$2:$O$3015,'Web Feed'!$B$2:$B$3015,Points!$A$4,'Web Feed'!$H$2:$H$3015,$B9)+SUMIFS('Web Feed'!$O$2:$O$3015,'Web Feed'!$B$2:$B$3015,Points!$A$4,'Web Feed'!$I$2:$I$3015,$B9)) | G9: =IF($B9="","",SUMIFS('Web Feed'!$O$2:$O$3015,'Web Feed'!$B$2:$B$3015,Points!$A$5,'Web Feed'!$F$2:$F$3015,$B9)+SUMIFS('Web Feed'!$O$2:$O$3015,'Web Feed'!$B$2:$B$3015,Points!$A$5,'Web Feed'!$G$2:$G$3015,$B9)+SUMIFS('Web Feed'!$O$2:$O$3015,'Web Feed'!$B$2:$B$3015,Points!$A$5,'Web Feed'!$H$2:$H$3015,$B9)+SUMIFS('Web Feed'!$O$2:$O$3015,'Web Feed'!$B$2:$B$3015,Points!$A$5,'Web Feed'!$I$2:$I$3015,$B9)) | H9: =IF($B9="","",SUMIFS('Web Feed'!$O$2:$O$3015,'Web Feed'!$B$2:$B$3015,Points!$A$6,'Web Feed'!$F$2:$F$3015,$B9)+SUMIFS('Web Feed'!$O$2:$O$3015,'Web Feed'!$B$2:$B$3015,Points!$A$6,'Web Feed'!$G$2:$G$3015,$B9)+SUMIFS('Web Feed'!$O$2:$O$3015,'Web Feed'!$B$2:$B$3015,Points!$A$6,'Web Feed'!$H$2:$H$3015,$B9)+SUMIFS('Web Feed'!$O$2:$O$3015,'Web Feed'!$B$2:$B$3015,Points!$A$6,'Web Feed'!$I$2:$I$3015,$B9)) | I9: =IF($B9="","",COUNTIFS('Web Feed'!$B$2:$B$3015,"OHW",'Web Feed'!$F$2:$F$3015,$B9)) | J9: =IF($B9="","",IFERROR(INDEX('Last Week'!$A$2:$A$301,MATCH($B9,'Last Week'!$B$2:$B$301,0)),"")) | K9: =IF(OR($B9="",$J9=""),"",$J9-$A9)
A10: =IF($B10="","",RANK($C10,$C$2:$C$500)) | B10: =IF(Players!$A10="","",Players!$A10) | C10: =IF($B10="","",SUM(D10:H10)) | D10: =IF($B10="","",SUMIFS('Web Feed'!$O$2:$O$3015,'Web Feed'!$B$2:$B$3015,Points!$A$2,'Web Feed'!$F$2:$F$3015,$B10)+SUMIFS('Web Feed'!$O$2:$O$3015,'Web Feed'!$B$2:$B$3015,Points!$A$2,'Web Feed'!$G$2:$G$3015,$B10)+SUMIFS('Web Feed'!$O$2:$O$3015,'Web Feed'!$B$2:$B$3015,Points!$A$2,'Web Feed'!$H$2:$H$3015,$B10)+SUMIFS('Web Feed'!$O$2:$O$3015,'Web Feed'!$B$2:$B$3015,Points!$A$2,'Web Feed'!$I$2:$I$3015,$B10)) | E10: =IF($B10="","",SUMIFS('Web Feed'!$O$2:$O$3015,'Web Feed'!$B$2:$B$3015,Points!$A$3,'Web Feed'!$F$2:$F$3015,$B10)+SUMIFS('Web Feed'!$O$2:$O$3015,'Web Feed'!$B$2:$B$3015,Points!$A$3,'Web Feed'!$G$2:$G$3015,$B10)+SUMIFS('Web Feed'!$O$2:$O$3015,'Web Feed'!$B$2:$B$3015,Points!$A$3,'Web Feed'!$H$2:$H$3015,$B10)+SUMIFS('Web Feed'!$O$2:$O$3015,'Web Feed'!$B$2:$B$3015,Points!$A$3,'Web Feed'!$I$2:$I$3015,$B10)) | F10: =IF($B10="","",SUMIFS('Web Feed'!$O$2:$O$3015,'Web Feed'!$B$2:$B$3015,Points!$A$4,'Web Feed'!$F$2:$F$3015,$B10)+SUMIFS('Web Feed'!$O$2:$O$3015,'Web Feed'!$B$2:$B$3015,Points!$A$4,'Web Feed'!$G$2:$G$3015,$B10)+SUMIFS('Web Feed'!$O$2:$O$3015,'Web Feed'!$B$2:$B$3015,Points!$A$4,'Web Feed'!$H$2:$H$3015,$B10)+SUMIFS('Web Feed'!$O$2:$O$3015,'Web Feed'!$B$2:$B$3015,Points!$A$4,'Web Feed'!$I$2:$I$3015,$B10)) | G10: =IF($B10="","",SUMIFS('Web Feed'!$O$2:$O$3015,'Web Feed'!$B$2:$B$3015,Points!$A$5,'Web Feed'!$F$2:$F$3015,$B10)+SUMIFS('Web Feed'!$O$2:$O$3015,'Web Feed'!$B$2:$B$3015,Points!$A$5,'Web Feed'!$G$2:$G$3015,$B10)+SUMIFS('Web Feed'!$O$2:$O$3015,'Web Feed'!$B$2:$B$3015,Points!$A$5,'Web Feed'!$H$2:$H$3015,$B10)+SUMIFS('Web Feed'!$O$2:$O$3015,'Web Feed'!$B$2:$B$3015,Points!$A$5,'Web Feed'!$I$2:$I$3015,$B10)) | H10: =IF($B10="","",SUMIFS('Web Feed'!$O$2:$O$3015,'Web Feed'!$B$2:$B$3015,Points!$A$6,'Web Feed'!$F$2:$F$3015,$B10)+SUMIFS('Web Feed'!$O$2:$O$3015,'Web Feed'!$B$2:$B$3015,Points!$A$6,'Web Feed'!$G$2:$G$3015,$B10)+SUMIFS('Web Feed'!$O$2:$O$3015,'Web Feed'!$B$2:$B$3015,Points!$A$6,'Web Feed'!$H$2:$H$3015,$B10)+SUMIFS('Web Feed'!$O$2:$O$3015,'Web Feed'!$B$2:$B$3015,Points!$A$6,'Web Feed'!$I$2:$I$3015,$B10)) | I10: =IF($B10="","",COUNTIFS('Web Feed'!$B$2:$B$3015,"OHW",'Web Feed'!$F$2:$F$3015,$B10)) | J10: =IF($B10="","",IFERROR(INDEX('Last Week'!$A$2:$A$301,MATCH($B10,'Last Week'!$B$2:$B$301,0)),"")) | K10: =IF(OR($B10="",$J10=""),"",$J10-$A10)
A11: =IF($B11="","",RANK($C11,$C$2:$C$500)) | B11: =IF(Players!$A11="","",Players!$A11) | C11: =IF($B11="","",SUM(D11:H11)) | D11: =IF($B11="","",SUMIFS('Web Feed'!$O$2:$O$3015,'Web Feed'!$B$2:$B$3015,Points!$A$2,'Web Feed'!$F$2:$F$3015,$B11)+SUMIFS('Web Feed'!$O$2:$O$3015,'Web Feed'!$B$2:$B$3015,Points!$A$2,'Web Feed'!$G$2:$G$3015,$B11)+SUMIFS('Web Feed'!$O$2:$O$3015,'Web Feed'!$B$2:$B$3015,Points!$A$2,'Web Feed'!$H$2:$H$3015,$B11)+SUMIFS('Web Feed'!$O$2:$O$3015,'Web Feed'!$B$2:$B$3015,Points!$A$2,'Web Feed'!$I$2:$I$3015,$B11)) | E11: =IF($B11="","",SUMIFS('Web Feed'!$O$2:$O$3015,'Web Feed'!$B$2:$B$3015,Points!$A$3,'Web Feed'!$F$2:$F$3015,$B11)+SUMIFS('Web Feed'!$O$2:$O$3015,'Web Feed'!$B$2:$B$3015,Points!$A$3,'Web Feed'!$G$2:$G$3015,$B11)+SUMIFS('Web Feed'!$O$2:$O$3015,'Web Feed'!$B$2:$B$3015,Points!$A$3,'Web Feed'!$H$2:$H$3015,$B11)+SUMIFS('Web Feed'!$O$2:$O$3015,'Web Feed'!$B$2:$B$3015,Points!$A$3,'Web Feed'!$I$2:$I$3015,$B11)) | F11: =IF($B11="","",SUMIFS('Web Feed'!$O$2:$O$3015,'Web Feed'!$B$2:$B$3015,Points!$A$4,'Web Feed'!$F$2:$F$3015,$B11)+SUMIFS('Web Feed'!$O$2:$O$3015,'Web Feed'!$B$2:$B$3015,Points!$A$4,'Web Feed'!$G$2:$G$3015,$B11)+SUMIFS('Web Feed'!$O$2:$O$3015,'Web Feed'!$B$2:$B$3015,Points!$A$4,'Web Feed'!$H$2:$H$3015,$B11)+SUMIFS('Web Feed'!$O$2:$O$3015,'Web Feed'!$B$2:$B$3015,Points!$A$4,'Web Feed'!$I$2:$I$3015,$B11)) | G11: =IF($B11="","",SUMIFS('Web Feed'!$O$2:$O$3015,'Web Feed'!$B$2:$B$3015,Points!$A$5,'Web Feed'!$F$2:$F$3015,$B11)+SUMIFS('Web Feed'!$O$2:$O$3015,'Web Feed'!$B$2:$B$3015,Points!$A$5,'Web Feed'!$G$2:$G$3015,$B11)+SUMIFS('Web Feed'!$O$2:$O$3015,'Web Feed'!$B$2:$B$3015,Points!$A$5,'Web Feed'!$H$2:$H$3015,$B11)+SUMIFS('Web Feed'!$O$2:$O$3015,'Web Feed'!$B$2:$B$3015,Points!$A$5,'Web Feed'!$I$2:$I$3015,$B11)) | H11: =IF($B11="","",SUMIFS('Web Feed'!$O$2:$O$3015,'Web Feed'!$B$2:$B$3015,Points!$A$6,'Web Feed'!$F$2:$F$3015,$B11)+SUMIFS('Web Feed'!$O$2:$O$3015,'Web Feed'!$B$2:$B$3015,Points!$A$6,'Web Feed'!$G$2:$G$3015,$B11)+SUMIFS('Web Feed'!$O$2:$O$3015,'Web Feed'!$B$2:$B$3015,Points!$A$6,'Web Feed'!$H$2:$H$3015,$B11)+SUMIFS('Web Feed'!$O$2:$O$3015,'Web Feed'!$B$2:$B$3015,Points!$A$6,'Web Feed'!$I$2:$I$3015,$B11)) | I11: =IF($B11="","",COUNTIFS('Web Feed'!$B$2:$B$3015,"OHW",'Web Feed'!$F$2:$F$3015,$B11)) | J11: =IF($B11="","",IFERROR(INDEX('Last Week'!$A$2:$A$301,MATCH($B11,'Last Week'!$B$2:$B$301,0)),"")) | K11: =IF(OR($B11="",$J11=""),"",$J11-$A11)
A12: =IF($B12="","",RANK($C12,$C$2:$C$500)) | B12: =IF(Players!$A12="","",Players!$A12) | C12: =IF($B12="","",SUM(D12:H12)) | D12: =IF($B12="","",SUMIFS('Web Feed'!$O$2:$O$3015,'Web Feed'!$B$2:$B$3015,Points!$A$2,'Web Feed'!$F$2:$F$3015,$B12)+SUMIFS('Web Feed'!$O$2:$O$3015,'Web Feed'!$B$2:$B$3015,Points!$A$2,'Web Feed'!$G$2:$G$3015,$B12)+SUMIFS('Web Feed'!$O$2:$O$3015,'Web Feed'!$B$2:$B$3015,Points!$A$2,'Web Feed'!$H$2:$H$3015,$B12)+SUMIFS('Web Feed'!$O$2:$O$3015,'Web Feed'!$B$2:$B$3015,Points!$A$2,'Web Feed'!$I$2:$I$3015,$B12)) | E12: =IF($B12="","",SUMIFS('Web Feed'!$O$2:$O$3015,'Web Feed'!$B$2:$B$3015,Points!$A$3,'Web Feed'!$F$2:$F$3015,$B12)+SUMIFS('Web Feed'!$O$2:$O$3015,'Web Feed'!$B$2:$B$3015,Points!$A$3,'Web Feed'!$G$2:$G$3015,$B12)+SUMIFS('Web Feed'!$O$2:$O$3015,'Web Feed'!$B$2:$B$3015,Points!$A$3,'Web Feed'!$H$2:$H$3015,$B12)+SUMIFS('Web Feed'!$O$2:$O$3015,'Web Feed'!$B$2:$B$3015,Points!$A$3,'Web Feed'!$I$2:$I$3015,$B12)) | F12: =IF($B12="","",SUMIFS('Web Feed'!$O$2:$O$3015,'Web Feed'!$B$2:$B$3015,Points!$A$4,'Web Feed'!$F$2:$F$3015,$B12)+SUMIFS('Web Feed'!$O$2:$O$3015,'Web Feed'!$B$2:$B$3015,Points!$A$4,'Web Feed'!$G$2:$G$3015,$B12)+SUMIFS('Web Feed'!$O$2:$O$3015,'Web Feed'!$B$2:$B$3015,Points!$A$4,'Web Feed'!$H$2:$H$3015,$B12)+SUMIFS('Web Feed'!$O$2:$O$3015,'Web Feed'!$B$2:$B$3015,Points!$A$4,'Web Feed'!$I$2:$I$3015,$B12)) | G12: =IF($B12="","",SUMIFS('Web Feed'!$O$2:$O$3015,'Web Feed'!$B$2:$B$3015,Points!$A$5,'Web Feed'!$F$2:$F$3015,$B12)+SUMIFS('Web Feed'!$O$2:$O$3015,'Web Feed'!$B$2:$B$3015,Points!$A$5,'Web Feed'!$G$2:$G$3015,$B12)+SUMIFS('Web Feed'!$O$2:$O$3015,'Web Feed'!$B$2:$B$3015,Points!$A$5,'Web Feed'!$H$2:$H$3015,$B12)+SUMIFS('Web Feed'!$O$2:$O$3015,'Web Feed'!$B$2:$B$3015,Points!$A$5,'Web Feed'!$I$2:$I$3015,$B12)) | H12: =IF($B12="","",SUMIFS('Web Feed'!$O$2:$O$3015,'Web Feed'!$B$2:$B$3015,Points!$A$6,'Web Feed'!$F$2:$F$3015,$B12)+SUMIFS('Web Feed'!$O$2:$O$3015,'Web Feed'!$B$2:$B$3015,Points!$A$6,'Web Feed'!$G$2:$G$3015,$B12)+SUMIFS('Web Feed'!$O$2:$O$3015,'Web Feed'!$B$2:$B$3015,Points!$A$6,'Web Feed'!$H$2:$H$3015,$B12)+SUMIFS('Web Feed'!$O$2:$O$3015,'Web Feed'!$B$2:$B$3015,Points!$A$6,'Web Feed'!$I$2:$I$3015,$B12)) | I12: =IF($B12="","",COUNTIFS('Web Feed'!$B$2:$B$3015,"OHW",'Web Feed'!$F$2:$F$3015,$B12)) | J12: =IF($B12="","",IFERROR(INDEX('Last Week'!$A$2:$A$301,MATCH($B12,'Last Week'!$B$2:$B$301,0)),"")) | K12: =IF(OR($B12="",$J12=""),"",$J12-$A12)
A13: =IF($B13="","",RANK($C13,$C$2:$C$500)) | B13: =IF(Players!$A13="","",Players!$A13) | C13: =IF($B13="","",SUM(D13:H13)) | D13: =IF($B13="","",SUMIFS('Web Feed'!$O$2:$O$3015,'Web Feed'!$B$2:$B$3015,Points!$A$2,'Web Feed'!$F$2:$F$3015,$B13)+SUMIFS('Web Feed'!$O$2:$O$3015,'Web Feed'!$B$2:$B$3015,Points!$A$2,'Web Feed'!$G$2:$G$3015,$B13)+SUMIFS('Web Feed'!$O$2:$O$3015,'Web Feed'!$B$2:$B$3015,Points!$A$2,'Web Feed'!$H$2:$H$3015,$B13)+SUMIFS('Web Feed'!$O$2:$O$3015,'Web Feed'!$B$2:$B$3015,Points!$A$2,'Web Feed'!$I$2:$I$3015,$B13)) | E13: =IF($B13="","",SUMIFS('Web Feed'!$O$2:$O$3015,'Web Feed'!$B$2:$B$3015,Points!$A$3,'Web Feed'!$F$2:$F$3015,$B13)+SUMIFS('Web Feed'!$O$2:$O$3015,'Web Feed'!$B$2:$B$3015,Points!$A$3,'Web Feed'!$G$2:$G$3015,$B13)+SUMIFS('Web Feed'!$O$2:$O$3015,'Web Feed'!$B$2:$B$3015,Points!$A$3,'Web Feed'!$H$2:$H$3015,$B13)+SUMIFS('Web Feed'!$O$2:$O$3015,'Web Feed'!$B$2:$B$3015,Points!$A$3,'Web Feed'!$I$2:$I$3015,$B13)) | F13: =IF($B13="","",SUMIFS('Web Feed'!$O$2:$O$3015,'Web Feed'!$B$2:$B$3015,Points!$A$4,'Web Feed'!$F$2:$F$3015,$B13)+SUMIFS('Web Feed'!$O$2:$O$3015,'Web Feed'!$B$2:$B$3015,Points!$A$4,'Web Feed'!$G$2:$G$3015,$B13)+SUMIFS('Web Feed'!$O$2:$O$3015,'Web Feed'!$B$2:$B$3015,Points!$A$4,'Web Feed'!$H$2:$H$3015,$B13)+SUMIFS('Web Feed'!$O$2:$O$3015,'Web Feed'!$B$2:$B$3015,Points!$A$4,'Web Feed'!$I$2:$I$3015,$B13)) | G13: =IF($B13="","",SUMIFS('Web Feed'!$O$2:$O$3015,'Web Feed'!$B$2:$B$3015,Points!$A$5,'Web Feed'!$F$2:$F$3015,$B13)+SUMIFS('Web Feed'!$O$2:$O$3015,'Web Feed'!$B$2:$B$3015,Points!$A$5,'Web Feed'!$G$2:$G$3015,$B13)+SUMIFS('Web Feed'!$O$2:$O$3015,'Web Feed'!$B$2:$B$3015,Points!$A$5,'Web Feed'!$H$2:$H$3015,$B13)+SUMIFS('Web Feed'!$O$2:$O$3015,'Web Feed'!$B$2:$B$3015,Points!$A$5,'Web Feed'!$I$2:$I$3015,$B13)) | H13: =IF($B13="","",SUMIFS('Web Feed'!$O$2:$O$3015,'Web Feed'!$B$2:$B$3015,Points!$A$6,'Web Feed'!$F$2:$F$3015,$B13)+SUMIFS('Web Feed'!$O$2:$O$3015,'Web Feed'!$B$2:$B$3015,Points!$A$6,'Web Feed'!$G$2:$G$3015,$B13)+SUMIFS('Web Feed'!$O$2:$O$3015,'Web Feed'!$B$2:$B$3015,Points!$A$6,'Web Feed'!$H$2:$H$3015,$B13)+SUMIFS('Web Feed'!$O$2:$O$3015,'Web Feed'!$B$2:$B$3015,Points!$A$6,'Web Feed'!$I$2:$I$3015,$B13)) | I13: =IF($B13="","",COUNTIFS('Web Feed'!$B$2:$B$3015,"OHW",'Web Feed'!$F$2:$F$3015,$B13)) | J13: =IF($B13="","",IFERROR(INDEX('Last Week'!$A$2:$A$301,MATCH($B13,'Last Week'!$B$2:$B$301,0)),"")) | K13: =IF(OR($B13="",$J13=""),"",$J13-$A13)
... A500: =IF($B500="","",RANK($C500,$C$2:$C$500)) | B500: =IF(Players!$A500="","",Players!$A500) | C500: =IF($B500="","",SUM(D500:H500)) | D500: =IF($B500="","",SUMIFS('Web Feed'!$O$2:$O$3015,'Web Feed'!$B$2:$B$3015,Points!$A$2,'Web Feed'!$F$2:$F$3015,$B500)+SUMIFS('Web Feed'!$O$2:$O$3015,'Web Feed'!$B$2:$B$3015,Points!$A$2,'Web Feed'!$G$2:$G$3015,$B500)+SUMIFS('Web Feed'!$O$2:$O$3015,'Web Feed'!$B$2:$B$3015,Points!$A$2,'Web Feed'!$H$2:$H$3015,$B500)+SUMIFS('Web Feed'!$O$2:$O$3015,'Web Feed'!$B$2:$B$3015,Points!$A$2,'Web Feed'!$I$2:$I$3015,$B500)) | E500: =IF($B500="","",SUMIFS('Web Feed'!$O$2:$O$3015,'Web Feed'!$B$2:$B$3015,Points!$A$3,'Web Feed'!$F$2:$F$3015,$B500)+SUMIFS('Web Feed'!$O$2:$O$3015,'Web Feed'!$B$2:$B$3015,Points!$A$3,'Web Feed'!$G$2:$G$3015,$B500)+SUMIFS('Web Feed'!$O$2:$O$3015,'Web Feed'!$B$2:$B$3015,Points!$A$3,'Web Feed'!$H$2:$H$3015,$B500)+SUMIFS('Web Feed'!$O$2:$O$3015,'Web Feed'!$B$2:$B$3015,Points!$A$3,'Web Feed'!$I$2:$I$3015,$B500)) | F500: =IF($B500="","",SUMIFS('Web Feed'!$O$2:$O$3015,'Web Feed'!$B$2:$B$3015,Points!$A$4,'Web Feed'!$F$2:$F$3015,$B500)+SUMIFS('Web Feed'!$O$2:$O$3015,'Web Feed'!$B$2:$B$3015,Points!$A$4,'Web Feed'!$G$2:$G$3015,$B500)+SUMIFS('Web Feed'!$O$2:$O$3015,'Web Feed'!$B$2:$B$3015,Points!$A$4,'Web Feed'!$H$2:$H$3015,$B500)+SUMIFS('Web Feed'!$O$2:$O$3015,'Web Feed'!$B$2:$B$3015,Points!$A$4,'Web Feed'!$I$2:$I$3015,$B500)) | G500: =IF($B500="","",SUMIFS('Web Feed'!$O$2:$O$3015,'Web Feed'!$B$2:$B$3015,Points!$A$5,'Web Feed'!$F$2:$F$3015,$B500)+SUMIFS('Web Feed'!$O$2:$O$3015,'Web Feed'!$B$2:$B$3015,Points!$A$5,'Web Feed'!$G$2:$G$3015,$B500)+SUMIFS('Web Feed'!$O$2:$O$3015,'Web Feed'!$B$2:$B$3015,Points!$A$5,'Web Feed'!$H$2:$H$3015,$B500)+SUMIFS('Web Feed'!$O$2:$O$3015,'Web Feed'!$B$2:$B$3015,Points!$A$5,'Web Feed'!$I$2:$I$3015,$B500)) | H500: =IF($B500="","",SUMIFS('Web Feed'!$O$2:$O$3015,'Web Feed'!$B$2:$B$3015,Points!$A$6,'Web Feed'!$F$2:$F$3015,$B500)+SUMIFS('Web Feed'!$O$2:$O$3015,'Web Feed'!$B$2:$B$3015,Points!$A$6,'Web Feed'!$G$2:$G$3015,$B500)+SUMIFS('Web Feed'!$O$2:$O$3015,'Web Feed'!$B$2:$B$3015,Points!$A$6,'Web Feed'!$H$2:$H$3015,$B500)+SUMIFS('Web Feed'!$O$2:$O$3015,'Web Feed'!$B$2:$B$3015,Points!$A$6,'Web Feed'!$I$2:$I$3015,$B500)) | I500: =IF($B500="","",COUNTIFS('Web Feed'!$B$2:$B$3015,"OHW",'Web Feed'!$F$2:$F$3015,$B500)) | J500: =IF($B500="","",IFERROR(INDEX('Last Week'!$A$2:$A$301,MATCH($B500,'Last Week'!$B$2:$B$301,0)),"")) | K500: =IF(OR($B500="",$J500=""),"",$J500-$A500)

Sheet Last Week
A1: Rank | B1: Player | C1: Cup Total | E1: Filled by the Star City Cup script when a new OHW week starts. No need to edit.

Sheet Players
A1: Player | B1: Division (Open or Senior)

Sheet Club Championship
A1: Club Championship | D1: One row per player. Enter their best qualifying score; add the bracket result for the top 16.
A2: Status | B2: Not started | C2: In progress: points are projected from the leaderboard. Final: points are official and the scores lock.
A3: End date
A5: Player | B5: Best Qualifying Score (strokes) | C5: Bracket Result (top 16) | D5: Qualifying Rank | E5: Field | F5: Points | G5: Status | H5: Check
D6: =IF(OR($A6="",NOT(ISNUMBER($B6))),"",COUNTIF($B$6:$B$155,"<"&$B6)+1) | E6: =IF($A6="","",COUNT($B$6:$B$155)) | F6: =IF(OR($A6="",$B$2="Not started"),"",IF($C6<>"",IFERROR(VLOOKUP($C6,Points!$D$2:$E$6,2,FALSE),""),IF(NOT(ISNUMBER($B6)),"",IF($D6<=16,Points!$E$6,IF($D6<=32,Points!$H$2,Points!$H$3))))) | G6: =IF($A6="","",IF($B$2="Final","Final",IF($B$2="In progress","Projected","Not started"))) | H6: =IF($A6="","",IF(COUNTIF(Players!$A$2:$A$500,$A6)=0,"Player is not on the Players tab",IF(COUNTIF($A$6:$A$155,$A6)>1,"Player is listed twice",IF($B$2="Not started","Set Status to In progress to count points",IF(AND($C6="",NOT(ISNUMBER($B6))),"Enter a qualifying score",IF(AND($C6<>"",ISNUMBER($D6),N($D6)>16),"Bracket result for a player ranked below 16th",IF(AND($B$2="Final",$C6="",N($D6)<=16),"Top 16: enter the bracket result","OK")))))))
D7: =IF(OR($A7="",NOT(ISNUMBER($B7))),"",COUNTIF($B$6:$B$155,"<"&$B7)+1) | E7: =IF($A7="","",COUNT($B$6:$B$155)) | F7: =IF(OR($A7="",$B$2="Not started"),"",IF($C7<>"",IFERROR(VLOOKUP($C7,Points!$D$2:$E$6,2,FALSE),""),IF(NOT(ISNUMBER($B7)),"",IF($D7<=16,Points!$E$6,IF($D7<=32,Points!$H$2,Points!$H$3))))) | G7: =IF($A7="","",IF($B$2="Final","Final",IF($B$2="In progress","Projected","Not started"))) | H7: =IF($A7="","",IF(COUNTIF(Players!$A$2:$A$500,$A7)=0,"Player is not on the Players tab",IF(COUNTIF($A$6:$A$155,$A7)>1,"Player is listed twice",IF($B$2="Not started","Set Status to In progress to count points",IF(AND($C7="",NOT(ISNUMBER($B7))),"Enter a qualifying score",IF(AND($C7<>"",ISNUMBER($D7),N($D7)>16),"Bracket result for a player ranked below 16th",IF(AND($B$2="Final",$C7="",N($D7)<=16),"Top 16: enter the bracket result","OK")))))))
D8: =IF(OR($A8="",NOT(ISNUMBER($B8))),"",COUNTIF($B$6:$B$155,"<"&$B8)+1) | E8: =IF($A8="","",COUNT($B$6:$B$155)) | F8: =IF(OR($A8="",$B$2="Not started"),"",IF($C8<>"",IFERROR(VLOOKUP($C8,Points!$D$2:$E$6,2,FALSE),""),IF(NOT(ISNUMBER($B8)),"",IF($D8<=16,Points!$E$6,IF($D8<=32,Points!$H$2,Points!$H$3))))) | G8: =IF($A8="","",IF($B$2="Final","Final",IF($B$2="In progress","Projected","Not started"))) | H8: =IF($A8="","",IF(COUNTIF(Players!$A$2:$A$500,$A8)=0,"Player is not on the Players tab",IF(COUNTIF($A$6:$A$155,$A8)>1,"Player is listed twice",IF($B$2="Not started","Set Status to In progress to count points",IF(AND($C8="",NOT(ISNUMBER($B8))),"Enter a qualifying score",IF(AND($C8<>"",ISNUMBER($D8),N($D8)>16),"Bracket result for a player ranked below 16th",IF(AND($B$2="Final",$C8="",N($D8)<=16),"Top 16: enter the bracket result","OK")))))))
D9: =IF(OR($A9="",NOT(ISNUMBER($B9))),"",COUNTIF($B$6:$B$155,"<"&$B9)+1) | E9: =IF($A9="","",COUNT($B$6:$B$155)) | F9: =IF(OR($A9="",$B$2="Not started"),"",IF($C9<>"",IFERROR(VLOOKUP($C9,Points!$D$2:$E$6,2,FALSE),""),IF(NOT(ISNUMBER($B9)),"",IF($D9<=16,Points!$E$6,IF($D9<=32,Points!$H$2,Points!$H$3))))) | G9: =IF($A9="","",IF($B$2="Final","Final",IF($B$2="In progress","Projected","Not started"))) | H9: =IF($A9="","",IF(COUNTIF(Players!$A$2:$A$500,$A9)=0,"Player is not on the Players tab",IF(COUNTIF($A$6:$A$155,$A9)>1,"Player is listed twice",IF($B$2="Not started","Set Status to In progress to count points",IF(AND($C9="",NOT(ISNUMBER($B9))),"Enter a qualifying score",IF(AND($C9<>"",ISNUMBER($D9),N($D9)>16),"Bracket result for a player ranked below 16th",IF(AND($B$2="Final",$C9="",N($D9)<=16),"Top 16: enter the bracket result","OK")))))))
D10: =IF(OR($A10="",NOT(ISNUMBER($B10))),"",COUNTIF($B$6:$B$155,"<"&$B10)+1) | E10: =IF($A10="","",COUNT($B$6:$B$155)) | F10: =IF(OR($A10="",$B$2="Not started"),"",IF($C10<>"",IFERROR(VLOOKUP($C10,Points!$D$2:$E$6,2,FALSE),""),IF(NOT(ISNUMBER($B10)),"",IF($D10<=16,Points!$E$6,IF($D10<=32,Points!$H$2,Points!$H$3))))) | G10: =IF($A10="","",IF($B$2="Final","Final",IF($B$2="In progress","Projected","Not started"))) | H10: =IF($A10="","",IF(COUNTIF(Players!$A$2:$A$500,$A10)=0,"Player is not on the Players tab",IF(COUNTIF($A$6:$A$155,$A10)>1,"Player is listed twice",IF($B$2="Not started","Set Status to In progress to count points",IF(AND($C10="",NOT(ISNUMBER($B10))),"Enter a qualifying score",IF(AND($C10<>"",ISNUMBER($D10),N($D10)>16),"Bracket result for a player ranked below 16th",IF(AND($B$2="Final",$C10="",N($D10)<=16),"Top 16: enter the bracket result","OK")))))))
D11: =IF(OR($A11="",NOT(ISNUMBER($B11))),"",COUNTIF($B$6:$B$155,"<"&$B11)+1) | E11: =IF($A11="","",COUNT($B$6:$B$155)) | F11: =IF(OR($A11="",$B$2="Not started"),"",IF($C11<>"",IFERROR(VLOOKUP($C11,Points!$D$2:$E$6,2,FALSE),""),IF(NOT(ISNUMBER($B11)),"",IF($D11<=16,Points!$E$6,IF($D11<=32,Points!$H$2,Points!$H$3))))) | G11: =IF($A11="","",IF($B$2="Final","Final",IF($B$2="In progress","Projected","Not started"))) | H11: =IF($A11="","",IF(COUNTIF(Players!$A$2:$A$500,$A11)=0,"Player is not on the Players tab",IF(COUNTIF($A$6:$A$155,$A11)>1,"Player is listed twice",IF($B$2="Not started","Set Status to In progress to count points",IF(AND($C11="",NOT(ISNUMBER($B11))),"Enter a qualifying score",IF(AND($C11<>"",ISNUMBER($D11),N($D11)>16),"Bracket result for a player ranked below 16th",IF(AND($B$2="Final",$C11="",N($D11)<=16),"Top 16: enter the bracket result","OK")))))))
D12: =IF(OR($A12="",NOT(ISNUMBER($B12))),"",COUNTIF($B$6:$B$155,"<"&$B12)+1) | E12: =IF($A12="","",COUNT($B$6:$B$155)) | F12: =IF(OR($A12="",$B$2="Not started"),"",IF($C12<>"",IFERROR(VLOOKUP($C12,Points!$D$2:$E$6,2,FALSE),""),IF(NOT(ISNUMBER($B12)),"",IF($D12<=16,Points!$E$6,IF($D12<=32,Points!$H$2,Points!$H$3))))) | G12: =IF($A12="","",IF($B$2="Final","Final",IF($B$2="In progress","Projected","Not started"))) | H12: =IF($A12="","",IF(COUNTIF(Players!$A$2:$A$500,$A12)=0,"Player is not on the Players tab",IF(COUNTIF($A$6:$A$155,$A12)>1,"Player is listed twice",IF($B$2="Not started","Set Status to In progress to count points",IF(AND($C12="",NOT(ISNUMBER($B12))),"Enter a qualifying score",IF(AND($C12<>"",ISNUMBER($D12),N($D12)>16),"Bracket result for a player ranked below 16th",IF(AND($B$2="Final",$C12="",N($D12)<=16),"Top 16: enter the bracket result","OK")))))))
D13: =IF(OR($A13="",NOT(ISNUMBER($B13))),"",COUNTIF($B$6:$B$155,"<"&$B13)+1) | E13: =IF($A13="","",COUNT($B$6:$B$155)) | F13: =IF(OR($A13="",$B$2="Not started"),"",IF($C13<>"",IFERROR(VLOOKUP($C13,Points!$D$2:$E$6,2,FALSE),""),IF(NOT(ISNUMBER($B13)),"",IF($D13<=16,Points!$E$6,IF($D13<=32,Points!$H$2,Points!$H$3))))) | G13: =IF($A13="","",IF($B$2="Final","Final",IF($B$2="In progress","Projected","Not started"))) | H13: =IF($A13="","",IF(COUNTIF(Players!$A$2:$A$500,$A13)=0,"Player is not on the Players tab",IF(COUNTIF($A$6:$A$155,$A13)>1,"Player is listed twice",IF($B$2="Not started","Set Status to In progress to count points",IF(AND($C13="",NOT(ISNUMBER($B13))),"Enter a qualifying score",IF(AND($C13<>"",ISNUMBER($D13),N($D13)>16),"Bracket result for a player ranked below 16th",IF(AND($B$2="Final",$C13="",N($D13)<=16),"Top 16: enter the bracket result","OK")))))))
D14: =IF(OR($A14="",NOT(ISNUMBER($B14))),"",COUNTIF($B$6:$B$155,"<"&$B14)+1) | E14: =IF($A14="","",COUNT($B$6:$B$155)) | F14: =IF(OR($A14="",$B$2="Not started"),"",IF($C14<>"",IFERROR(VLOOKUP($C14,Points!$D$2:$E$6,2,FALSE),""),IF(NOT(ISNUMBER($B14)),"",IF($D14<=16,Points!$E$6,IF($D14<=32,Points!$H$2,Points!$H$3))))) | G14: =IF($A14="","",IF($B$2="Final","Final",IF($B$2="In progress","Projected","Not started"))) | H14: =IF($A14="","",IF(COUNTIF(Players!$A$2:$A$500,$A14)=0,"Player is not on the Players tab",IF(COUNTIF($A$6:$A$155,$A14)>1,"Player is listed twice",IF($B$2="Not started","Set Status to In progress to count points",IF(AND($C14="",NOT(ISNUMBER($B14))),"Enter a qualifying score",IF(AND($C14<>"",ISNUMBER($D14),N($D14)>16),"Bracket result for a player ranked below 16th",IF(AND($B$2="Final",$C14="",N($D14)<=16),"Top 16: enter the bracket result","OK")))))))
D15: =IF(OR($A15="",NOT(ISNUMBER($B15))),"",COUNTIF($B$6:$B$155,"<"&$B15)+1) | E15: =IF($A15="","",COUNT($B$6:$B$155)) | F15: =IF(OR($A15="",$B$2="Not started"),"",IF($C15<>"",IFERROR(VLOOKUP($C15,Points!$D$2:$E$6,2,FALSE),""),IF(NOT(ISNUMBER($B15)),"",IF($D15<=16,Points!$E$6,IF($D15<=32,Points!$H$2,Points!$H$3))))) | G15: =IF($A15="","",IF($B$2="Final","Final",IF($B$2="In progress","Projected","Not started"))) | H15: =IF($A15="","",IF(COUNTIF(Players!$A$2:$A$500,$A15)=0,"Player is not on the Players tab",IF(COUNTIF($A$6:$A$155,$A15)>1,"Player is listed twice",IF($B$2="Not started","Set Status to In progress to count points",IF(AND($C15="",NOT(ISNUMBER($B15))),"Enter a qualifying score",IF(AND($C15<>"",ISNUMBER($D15),N($D15)>16),"Bracket result for a player ranked below 16th",IF(AND($B$2="Final",$C15="",N($D15)<=16),"Top 16: enter the bracket result","OK")))))))
D16: =IF(OR($A16="",NOT(ISNUMBER($B16))),"",COUNTIF($B$6:$B$155,"<"&$B16)+1) | E16: =IF($A16="","",COUNT($B$6:$B$155)) | F16: =IF(OR($A16="",$B$2="Not started"),"",IF($C16<>"",IFERROR(VLOOKUP($C16,Points!$D$2:$E$6,2,FALSE),""),IF(NOT(ISNUMBER($B16)),"",IF($D16<=16,Points!$E$6,IF($D16<=32,Points!$H$2,Points!$H$3))))) | G16: =IF($A16="","",IF($B$2="Final","Final",IF($B$2="In progress","Projected","Not started"))) | H16: =IF($A16="","",IF(COUNTIF(Players!$A$2:$A$500,$A16)=0,"Player is not on the Players tab",IF(COUNTIF($A$6:$A$155,$A16)>1,"Player is listed twice",IF($B$2="Not started","Set Status to In progress to count points",IF(AND($C16="",NOT(ISNUMBER($B16))),"Enter a qualifying score",IF(AND($C16<>"",ISNUMBER($D16),N($D16)>16),"Bracket result for a player ranked below 16th",IF(AND($B$2="Final",$C16="",N($D16)<=16),"Top 16: enter the bracket result","OK")))))))
D17: =IF(OR($A17="",NOT(ISNUMBER($B17))),"",COUNTIF($B$6:$B$155,"<"&$B17)+1) | E17: =IF($A17="","",COUNT($B$6:$B$155)) | F17: =IF(OR($A17="",$B$2="Not started"),"",IF($C17<>"",IFERROR(VLOOKUP($C17,Points!$D$2:$E$6,2,FALSE),""),IF(NOT(ISNUMBER($B17)),"",IF($D17<=16,Points!$E$6,IF($D17<=32,Points!$H$2,Points!$H$3))))) | G17: =IF($A17="","",IF($B$2="Final","Final",IF($B$2="In progress","Projected","Not started"))) | H17: =IF($A17="","",IF(COUNTIF(Players!$A$2:$A$500,$A17)=0,"Player is not on the Players tab",IF(COUNTIF($A$6:$A$155,$A17)>1,"Player is listed twice",IF($B$2="Not started","Set Status to In progress to count points",IF(AND($C17="",NOT(ISNUMBER($B17))),"Enter a qualifying score",IF(AND($C17<>"",ISNUMBER($D17),N($D17)>16),"Bracket result for a player ranked below 16th",IF(AND($B$2="Final",$C17="",N($D17)<=16),"Top 16: enter the bracket result","OK")))))))
... D155: =IF(OR($A155="",NOT(ISNUMBER($B155))),"",COUNTIF($B$6:$B$155,"<"&$B155)+1) | E155: =IF($A155="","",COUNT($B$6:$B$155)) | F155: =IF(OR($A155="",$B$2="Not started"),"",IF($C155<>"",IFERROR(VLOOKUP($C155,Points!$D$2:$E$6,2,FALSE),""),IF(NOT(ISNUMBER($B155)),"",IF($D155<=16,Points!$E$6,IF($D155<=32,Points!$H$2,Points!$H$3))))) | G155: =IF($A155="","",IF($B$2="Final","Final",IF($B$2="In progress","Projected","Not started"))) | H155: =IF($A155="","",IF(COUNTIF(Players!$A$2:$A$500,$A155)=0,"Player is not on the Players tab",IF(COUNTIF($A$6:$A$155,$A155)>1,"Player is listed twice",IF($B$2="Not started","Set Status to In progress to count points",IF(AND($C155="",NOT(ISNUMBER($B155))),"Enter a qualifying score",IF(AND($C155<>"",ISNUMBER($D155),N($D155)>16),"Bracket result for a player ranked below 16th",IF(AND($B$2="Final",$C155="",N($D155)<=16),"Top 16: enter the bracket result","OK")))))))

Sheet Masters
A1: Masters | D1: One row per player. Enter their best score so far in strokes; type over it when they beat it.
A2: Status | B2: Not started | C2: In progress: points are projected from the leaderboard. Final: points are official and the scores lock.
A3: End date
A4: Division comes from the Players tab. Open and Senior are ranked separately. Pick one Winner per division; anyone tied with the winner is scored from 2nd place down.
A6: Player | B6: Best Score (strokes) | C6: Winner | D6: Division | E6: Rank | F6: Field | G6: Points | H6: Status | I6: Check | J6: Tied
D7: =IF($A7="","",IFERROR(IF(VLOOKUP($A7,Players!$A$2:$B$500,2,FALSE)="","Open",VLOOKUP($A7,Players!$A$2:$B$500,2,FALSE)),"Open")) | E7: =IF(OR($A7="",NOT(ISNUMBER($B7))),"",IF($C7="Winner",1,COUNTIFS($D$7:$D$156,$D7,$B$7:$B$156,"<"&$B7)+1+IF(AND(NOT($C7="Winner"),COUNTIFS($D$7:$D$156,$D7,$C$7:$C$156,"Winner",$B$7:$B$156,$B7)>0),1,0))) | F7: =IF(OR($A7="",NOT(ISNUMBER($B7))),"",COUNTIFS($D$7:$D$156,$D7,$B$7:$B$156,">0")) | G7: =IF(OR(OR($A7="",NOT(ISNUMBER($B7))),$B$2="Not started"),"",IF($C7="Winner",Points!$B$3,ROUND(Points!$B$3*IF($F7<=1,1,Points!$H$7+(1-Points!$H$7)*((($F7-$E7)*(($F7-$E7)+1)/2)^2-((($F7-$E7-$J7+1)-1)*($F7-$E7-$J7+1)/2)^2)/($J7*($F7-1)^3)),0))) | H7: =IF($A7="","",IF($B$2="Final","Final",IF($B$2="In progress","Projected","Not started"))) | I7: =IF($A7="","",IF(COUNTIF(Players!$A$2:$A$500,$A7)=0,"Player is not on the Players tab",IF(COUNTIF($A$7:$A$156,$A7)>1,"Player is listed twice",IF(NOT(ISNUMBER($B7)),"Enter a score",IF(COUNTIFS($D$7:$D$156,$D7,$C$7:$C$156,"Winner")>1,"More than one "&$D7&" winner picked",IF(AND($C7="Winner",COUNTIFS($D$7:$D$156,$D7,$B$7:$B$156,"<"&$B7)>0),"The winner doesn't have the best "&$D7&" score",IF(AND($B$2="Final",COUNTIFS($D$7:$D$156,$D7,$C$7:$C$156,"Winner")=0),"Final: pick the "&$D7&" winner",IF($B$2="Not started","Set Status to In progress to count points","OK")))))))) | J7: =IF(OR($A7="",NOT(ISNUMBER($B7))),"",IF($C7="Winner",1,COUNTIFS($D$7:$D$156,$D7,$B$7:$B$156,$B7)-IF(AND(NOT($C7="Winner"),COUNTIFS($D$7:$D$156,$D7,$C$7:$C$156,"Winner",$B$7:$B$156,$B7)>0),1,0)))
D8: =IF($A8="","",IFERROR(IF(VLOOKUP($A8,Players!$A$2:$B$500,2,FALSE)="","Open",VLOOKUP($A8,Players!$A$2:$B$500,2,FALSE)),"Open")) | E8: =IF(OR($A8="",NOT(ISNUMBER($B8))),"",IF($C8="Winner",1,COUNTIFS($D$7:$D$156,$D8,$B$7:$B$156,"<"&$B8)+1+IF(AND(NOT($C8="Winner"),COUNTIFS($D$7:$D$156,$D8,$C$7:$C$156,"Winner",$B$7:$B$156,$B8)>0),1,0))) | F8: =IF(OR($A8="",NOT(ISNUMBER($B8))),"",COUNTIFS($D$7:$D$156,$D8,$B$7:$B$156,">0")) | G8: =IF(OR(OR($A8="",NOT(ISNUMBER($B8))),$B$2="Not started"),"",IF($C8="Winner",Points!$B$3,ROUND(Points!$B$3*IF($F8<=1,1,Points!$H$7+(1-Points!$H$7)*((($F8-$E8)*(($F8-$E8)+1)/2)^2-((($F8-$E8-$J8+1)-1)*($F8-$E8-$J8+1)/2)^2)/($J8*($F8-1)^3)),0))) | H8: =IF($A8="","",IF($B$2="Final","Final",IF($B$2="In progress","Projected","Not started"))) | I8: =IF($A8="","",IF(COUNTIF(Players!$A$2:$A$500,$A8)=0,"Player is not on the Players tab",IF(COUNTIF($A$7:$A$156,$A8)>1,"Player is listed twice",IF(NOT(ISNUMBER($B8)),"Enter a score",IF(COUNTIFS($D$7:$D$156,$D8,$C$7:$C$156,"Winner")>1,"More than one "&$D8&" winner picked",IF(AND($C8="Winner",COUNTIFS($D$7:$D$156,$D8,$B$7:$B$156,"<"&$B8)>0),"The winner doesn't have the best "&$D8&" score",IF(AND($B$2="Final",COUNTIFS($D$7:$D$156,$D8,$C$7:$C$156,"Winner")=0),"Final: pick the "&$D8&" winner",IF($B$2="Not started","Set Status to In progress to count points","OK")))))))) | J8: =IF(OR($A8="",NOT(ISNUMBER($B8))),"",IF($C8="Winner",1,COUNTIFS($D$7:$D$156,$D8,$B$7:$B$156,$B8)-IF(AND(NOT($C8="Winner"),COUNTIFS($D$7:$D$156,$D8,$C$7:$C$156,"Winner",$B$7:$B$156,$B8)>0),1,0)))
D9: =IF($A9="","",IFERROR(IF(VLOOKUP($A9,Players!$A$2:$B$500,2,FALSE)="","Open",VLOOKUP($A9,Players!$A$2:$B$500,2,FALSE)),"Open")) | E9: =IF(OR($A9="",NOT(ISNUMBER($B9))),"",IF($C9="Winner",1,COUNTIFS($D$7:$D$156,$D9,$B$7:$B$156,"<"&$B9)+1+IF(AND(NOT($C9="Winner"),COUNTIFS($D$7:$D$156,$D9,$C$7:$C$156,"Winner",$B$7:$B$156,$B9)>0),1,0))) | F9: =IF(OR($A9="",NOT(ISNUMBER($B9))),"",COUNTIFS($D$7:$D$156,$D9,$B$7:$B$156,">0")) | G9: =IF(OR(OR($A9="",NOT(ISNUMBER($B9))),$B$2="Not started"),"",IF($C9="Winner",Points!$B$3,ROUND(Points!$B$3*IF($F9<=1,1,Points!$H$7+(1-Points!$H$7)*((($F9-$E9)*(($F9-$E9)+1)/2)^2-((($F9-$E9-$J9+1)-1)*($F9-$E9-$J9+1)/2)^2)/($J9*($F9-1)^3)),0))) | H9: =IF($A9="","",IF($B$2="Final","Final",IF($B$2="In progress","Projected","Not started"))) | I9: =IF($A9="","",IF(COUNTIF(Players!$A$2:$A$500,$A9)=0,"Player is not on the Players tab",IF(COUNTIF($A$7:$A$156,$A9)>1,"Player is listed twice",IF(NOT(ISNUMBER($B9)),"Enter a score",IF(COUNTIFS($D$7:$D$156,$D9,$C$7:$C$156,"Winner")>1,"More than one "&$D9&" winner picked",IF(AND($C9="Winner",COUNTIFS($D$7:$D$156,$D9,$B$7:$B$156,"<"&$B9)>0),"The winner doesn't have the best "&$D9&" score",IF(AND($B$2="Final",COUNTIFS($D$7:$D$156,$D9,$C$7:$C$156,"Winner")=0),"Final: pick the "&$D9&" winner",IF($B$2="Not started","Set Status to In progress to count points","OK")))))))) | J9: =IF(OR($A9="",NOT(ISNUMBER($B9))),"",IF($C9="Winner",1,COUNTIFS($D$7:$D$156,$D9,$B$7:$B$156,$B9)-IF(AND(NOT($C9="Winner"),COUNTIFS($D$7:$D$156,$D9,$C$7:$C$156,"Winner",$B$7:$B$156,$B9)>0),1,0)))
D10: =IF($A10="","",IFERROR(IF(VLOOKUP($A10,Players!$A$2:$B$500,2,FALSE)="","Open",VLOOKUP($A10,Players!$A$2:$B$500,2,FALSE)),"Open")) | E10: =IF(OR($A10="",NOT(ISNUMBER($B10))),"",IF($C10="Winner",1,COUNTIFS($D$7:$D$156,$D10,$B$7:$B$156,"<"&$B10)+1+IF(AND(NOT($C10="Winner"),COUNTIFS($D$7:$D$156,$D10,$C$7:$C$156,"Winner",$B$7:$B$156,$B10)>0),1,0))) | F10: =IF(OR($A10="",NOT(ISNUMBER($B10))),"",COUNTIFS($D$7:$D$156,$D10,$B$7:$B$156,">0")) | G10: =IF(OR(OR($A10="",NOT(ISNUMBER($B10))),$B$2="Not started"),"",IF($C10="Winner",Points!$B$3,ROUND(Points!$B$3*IF($F10<=1,1,Points!$H$7+(1-Points!$H$7)*((($F10-$E10)*(($F10-$E10)+1)/2)^2-((($F10-$E10-$J10+1)-1)*($F10-$E10-$J10+1)/2)^2)/($J10*($F10-1)^3)),0))) | H10: =IF($A10="","",IF($B$2="Final","Final",IF($B$2="In progress","Projected","Not started"))) | I10: =IF($A10="","",IF(COUNTIF(Players!$A$2:$A$500,$A10)=0,"Player is not on the Players tab",IF(COUNTIF($A$7:$A$156,$A10)>1,"Player is listed twice",IF(NOT(ISNUMBER($B10)),"Enter a score",IF(COUNTIFS($D$7:$D$156,$D10,$C$7:$C$156,"Winner")>1,"More than one "&$D10&" winner picked",IF(AND($C10="Winner",COUNTIFS($D$7:$D$156,$D10,$B$7:$B$156,"<"&$B10)>0),"The winner doesn't have the best "&$D10&" score",IF(AND($B$2="Final",COUNTIFS($D$7:$D$156,$D10,$C$7:$C$156,"Winner")=0),"Final: pick the "&$D10&" winner",IF($B$2="Not started","Set Status to In progress to count points","OK")))))))) | J10: =IF(OR($A10="",NOT(ISNUMBER($B10))),"",IF($C10="Winner",1,COUNTIFS($D$7:$D$156,$D10,$B$7:$B$156,$B10)-IF(AND(NOT($C10="Winner"),COUNTIFS($D$7:$D$156,$D10,$C$7:$C$156,"Winner",$B$7:$B$156,$B10)>0),1,0)))
D11: =IF($A11="","",IFERROR(IF(VLOOKUP($A11,Players!$A$2:$B$500,2,FALSE)="","Open",VLOOKUP($A11,Players!$A$2:$B$500,2,FALSE)),"Open")) | E11: =IF(OR($A11="",NOT(ISNUMBER($B11))),"",IF($C11="Winner",1,COUNTIFS($D$7:$D$156,$D11,$B$7:$B$156,"<"&$B11)+1+IF(AND(NOT($C11="Winner"),COUNTIFS($D$7:$D$156,$D11,$C$7:$C$156,"Winner",$B$7:$B$156,$B11)>0),1,0))) | F11: =IF(OR($A11="",NOT(ISNUMBER($B11))),"",COUNTIFS($D$7:$D$156,$D11,$B$7:$B$156,">0")) | G11: =IF(OR(OR($A11="",NOT(ISNUMBER($B11))),$B$2="Not started"),"",IF($C11="Winner",Points!$B$3,ROUND(Points!$B$3*IF($F11<=1,1,Points!$H$7+(1-Points!$H$7)*((($F11-$E11)*(($F11-$E11)+1)/2)^2-((($F11-$E11-$J11+1)-1)*($F11-$E11-$J11+1)/2)^2)/($J11*($F11-1)^3)),0))) | H11: =IF($A11="","",IF($B$2="Final","Final",IF($B$2="In progress","Projected","Not started"))) | I11: =IF($A11="","",IF(COUNTIF(Players!$A$2:$A$500,$A11)=0,"Player is not on the Players tab",IF(COUNTIF($A$7:$A$156,$A11)>1,"Player is listed twice",IF(NOT(ISNUMBER($B11)),"Enter a score",IF(COUNTIFS($D$7:$D$156,$D11,$C$7:$C$156,"Winner")>1,"More than one "&$D11&" winner picked",IF(AND($C11="Winner",COUNTIFS($D$7:$D$156,$D11,$B$7:$B$156,"<"&$B11)>0),"The winner doesn't have the best "&$D11&" score",IF(AND($B$2="Final",COUNTIFS($D$7:$D$156,$D11,$C$7:$C$156,"Winner")=0),"Final: pick the "&$D11&" winner",IF($B$2="Not started","Set Status to In progress to count points","OK")))))))) | J11: =IF(OR($A11="",NOT(ISNUMBER($B11))),"",IF($C11="Winner",1,COUNTIFS($D$7:$D$156,$D11,$B$7:$B$156,$B11)-IF(AND(NOT($C11="Winner"),COUNTIFS($D$7:$D$156,$D11,$C$7:$C$156,"Winner",$B$7:$B$156,$B11)>0),1,0)))
D12: =IF($A12="","",IFERROR(IF(VLOOKUP($A12,Players!$A$2:$B$500,2,FALSE)="","Open",VLOOKUP($A12,Players!$A$2:$B$500,2,FALSE)),"Open")) | E12: =IF(OR($A12="",NOT(ISNUMBER($B12))),"",IF($C12="Winner",1,COUNTIFS($D$7:$D$156,$D12,$B$7:$B$156,"<"&$B12)+1+IF(AND(NOT($C12="Winner"),COUNTIFS($D$7:$D$156,$D12,$C$7:$C$156,"Winner",$B$7:$B$156,$B12)>0),1,0))) | F12: =IF(OR($A12="",NOT(ISNUMBER($B12))),"",COUNTIFS($D$7:$D$156,$D12,$B$7:$B$156,">0")) | G12: =IF(OR(OR($A12="",NOT(ISNUMBER($B12))),$B$2="Not started"),"",IF($C12="Winner",Points!$B$3,ROUND(Points!$B$3*IF($F12<=1,1,Points!$H$7+(1-Points!$H$7)*((($F12-$E12)*(($F12-$E12)+1)/2)^2-((($F12-$E12-$J12+1)-1)*($F12-$E12-$J12+1)/2)^2)/($J12*($F12-1)^3)),0))) | H12: =IF($A12="","",IF($B$2="Final","Final",IF($B$2="In progress","Projected","Not started"))) | I12: =IF($A12="","",IF(COUNTIF(Players!$A$2:$A$500,$A12)=0,"Player is not on the Players tab",IF(COUNTIF($A$7:$A$156,$A12)>1,"Player is listed twice",IF(NOT(ISNUMBER($B12)),"Enter a score",IF(COUNTIFS($D$7:$D$156,$D12,$C$7:$C$156,"Winner")>1,"More than one "&$D12&" winner picked",IF(AND($C12="Winner",COUNTIFS($D$7:$D$156,$D12,$B$7:$B$156,"<"&$B12)>0),"The winner doesn't have the best "&$D12&" score",IF(AND($B$2="Final",COUNTIFS($D$7:$D$156,$D12,$C$7:$C$156,"Winner")=0),"Final: pick the "&$D12&" winner",IF($B$2="Not started","Set Status to In progress to count points","OK")))))))) | J12: =IF(OR($A12="",NOT(ISNUMBER($B12))),"",IF($C12="Winner",1,COUNTIFS($D$7:$D$156,$D12,$B$7:$B$156,$B12)-IF(AND(NOT($C12="Winner"),COUNTIFS($D$7:$D$156,$D12,$C$7:$C$156,"Winner",$B$7:$B$156,$B12)>0),1,0)))
D13: =IF($A13="","",IFERROR(IF(VLOOKUP($A13,Players!$A$2:$B$500,2,FALSE)="","Open",VLOOKUP($A13,Players!$A$2:$B$500,2,FALSE)),"Open")) | E13: =IF(OR($A13="",NOT(ISNUMBER($B13))),"",IF($C13="Winner",1,COUNTIFS($D$7:$D$156,$D13,$B$7:$B$156,"<"&$B13)+1+IF(AND(NOT($C13="Winner"),COUNTIFS($D$7:$D$156,$D13,$C$7:$C$156,"Winner",$B$7:$B$156,$B13)>0),1,0))) | F13: =IF(OR($A13="",NOT(ISNUMBER($B13))),"",COUNTIFS($D$7:$D$156,$D13,$B$7:$B$156,">0")) | G13: =IF(OR(OR($A13="",NOT(ISNUMBER($B13))),$B$2="Not started"),"",IF($C13="Winner",Points!$B$3,ROUND(Points!$B$3*IF($F13<=1,1,Points!$H$7+(1-Points!$H$7)*((($F13-$E13)*(($F13-$E13)+1)/2)^2-((($F13-$E13-$J13+1)-1)*($F13-$E13-$J13+1)/2)^2)/($J13*($F13-1)^3)),0))) | H13: =IF($A13="","",IF($B$2="Final","Final",IF($B$2="In progress","Projected","Not started"))) | I13: =IF($A13="","",IF(COUNTIF(Players!$A$2:$A$500,$A13)=0,"Player is not on the Players tab",IF(COUNTIF($A$7:$A$156,$A13)>1,"Player is listed twice",IF(NOT(ISNUMBER($B13)),"Enter a score",IF(COUNTIFS($D$7:$D$156,$D13,$C$7:$C$156,"Winner")>1,"More than one "&$D13&" winner picked",IF(AND($C13="Winner",COUNTIFS($D$7:$D$156,$D13,$B$7:$B$156,"<"&$B13)>0),"The winner doesn't have the best "&$D13&" score",IF(AND($B$2="Final",COUNTIFS($D$7:$D$156,$D13,$C$7:$C$156,"Winner")=0),"Final: pick the "&$D13&" winner",IF($B$2="Not started","Set Status to In progress to count points","OK")))))))) | J13: =IF(OR($A13="",NOT(ISNUMBER($B13))),"",IF($C13="Winner",1,COUNTIFS($D$7:$D$156,$D13,$B$7:$B$156,$B13)-IF(AND(NOT($C13="Winner"),COUNTIFS($D$7:$D$156,$D13,$C$7:$C$156,"Winner",$B$7:$B$156,$B13)>0),1,0)))
D14: =IF($A14="","",IFERROR(IF(VLOOKUP($A14,Players!$A$2:$B$500,2,FALSE)="","Open",VLOOKUP($A14,Players!$A$2:$B$500,2,FALSE)),"Open")) | E14: =IF(OR($A14="",NOT(ISNUMBER($B14))),"",IF($C14="Winner",1,COUNTIFS($D$7:$D$156,$D14,$B$7:$B$156,"<"&$B14)+1+IF(AND(NOT($C14="Winner"),COUNTIFS($D$7:$D$156,$D14,$C$7:$C$156,"Winner",$B$7:$B$156,$B14)>0),1,0))) | F14: =IF(OR($A14="",NOT(ISNUMBER($B14))),"",COUNTIFS($D$7:$D$156,$D14,$B$7:$B$156,">0")) | G14: =IF(OR(OR($A14="",NOT(ISNUMBER($B14))),$B$2="Not started"),"",IF($C14="Winner",Points!$B$3,ROUND(Points!$B$3*IF($F14<=1,1,Points!$H$7+(1-Points!$H$7)*((($F14-$E14)*(($F14-$E14)+1)/2)^2-((($F14-$E14-$J14+1)-1)*($F14-$E14-$J14+1)/2)^2)/($J14*($F14-1)^3)),0))) | H14: =IF($A14="","",IF($B$2="Final","Final",IF($B$2="In progress","Projected","Not started"))) | I14: =IF($A14="","",IF(COUNTIF(Players!$A$2:$A$500,$A14)=0,"Player is not on the Players tab",IF(COUNTIF($A$7:$A$156,$A14)>1,"Player is listed twice",IF(NOT(ISNUMBER($B14)),"Enter a score",IF(COUNTIFS($D$7:$D$156,$D14,$C$7:$C$156,"Winner")>1,"More than one "&$D14&" winner picked",IF(AND($C14="Winner",COUNTIFS($D$7:$D$156,$D14,$B$7:$B$156,"<"&$B14)>0),"The winner doesn't have the best "&$D14&" score",IF(AND($B$2="Final",COUNTIFS($D$7:$D$156,$D14,$C$7:$C$156,"Winner")=0),"Final: pick the "&$D14&" winner",IF($B$2="Not started","Set Status to In progress to count points","OK")))))))) | J14: =IF(OR($A14="",NOT(ISNUMBER($B14))),"",IF($C14="Winner",1,COUNTIFS($D$7:$D$156,$D14,$B$7:$B$156,$B14)-IF(AND(NOT($C14="Winner"),COUNTIFS($D$7:$D$156,$D14,$C$7:$C$156,"Winner",$B$7:$B$156,$B14)>0),1,0)))
D15: =IF($A15="","",IFERROR(IF(VLOOKUP($A15,Players!$A$2:$B$500,2,FALSE)="","Open",VLOOKUP($A15,Players!$A$2:$B$500,2,FALSE)),"Open")) | E15: =IF(OR($A15="",NOT(ISNUMBER($B15))),"",IF($C15="Winner",1,COUNTIFS($D$7:$D$156,$D15,$B$7:$B$156,"<"&$B15)+1+IF(AND(NOT($C15="Winner"),COUNTIFS($D$7:$D$156,$D15,$C$7:$C$156,"Winner",$B$7:$B$156,$B15)>0),1,0))) | F15: =IF(OR($A15="",NOT(ISNUMBER($B15))),"",COUNTIFS($D$7:$D$156,$D15,$B$7:$B$156,">0")) | G15: =IF(OR(OR($A15="",NOT(ISNUMBER($B15))),$B$2="Not started"),"",IF($C15="Winner",Points!$B$3,ROUND(Points!$B$3*IF($F15<=1,1,Points!$H$7+(1-Points!$H$7)*((($F15-$E15)*(($F15-$E15)+1)/2)^2-((($F15-$E15-$J15+1)-1)*($F15-$E15-$J15+1)/2)^2)/($J15*($F15-1)^3)),0))) | H15: =IF($A15="","",IF($B$2="Final","Final",IF($B$2="In progress","Projected","Not started"))) | I15: =IF($A15="","",IF(COUNTIF(Players!$A$2:$A$500,$A15)=0,"Player is not on the Players tab",IF(COUNTIF($A$7:$A$156,$A15)>1,"Player is listed twice",IF(NOT(ISNUMBER($B15)),"Enter a score",IF(COUNTIFS($D$7:$D$156,$D15,$C$7:$C$156,"Winner")>1,"More than one "&$D15&" winner picked",IF(AND($C15="Winner",COUNTIFS($D$7:$D$156,$D15,$B$7:$B$156,"<"&$B15)>0),"The winner doesn't have the best "&$D15&" score",IF(AND($B$2="Final",COUNTIFS($D$7:$D$156,$D15,$C$7:$C$156,"Winner")=0),"Final: pick the "&$D15&" winner",IF($B$2="Not started","Set Status to In progress to count points","OK")))))))) | J15: =IF(OR($A15="",NOT(ISNUMBER($B15))),"",IF($C15="Winner",1,COUNTIFS($D$7:$D$156,$D15,$B$7:$B$156,$B15)-IF(AND(NOT($C15="Winner"),COUNTIFS($D$7:$D$156,$D15,$C$7:$C$156,"Winner",$B$7:$B$156,$B15)>0),1,0)))
